
Starting partition number:  0
  0%|                                                                                                                                                                             | 0/30 [00:00<?, ?it/s]

  3%|█████▌                                                                                                                                                               | 1/30 [00:12<05:53, 12.17s/it]
Test set: Average loss: 0.0673, Accuracy: 4207/63485 (7%)

  7%|███████████                                                                                                                                                          | 2/30 [00:24<05:36, 12.01s/it]
Test set: Average loss: 0.0639, Accuracy: 4278/63485 (7%)

 10%|████████████████▌                                                                                                                                                    | 3/30 [00:35<05:21, 11.91s/it]
Test set: Average loss: 0.0628, Accuracy: 4375/63485 (7%)

 13%|██████████████████████                                                                                                                                               | 4/30 [00:47<05:09, 11.92s/it]
Test set: Average loss: 0.0619, Accuracy: 4599/63485 (7%)

 17%|███████████████████████████▌                                                                                                                                         | 5/30 [00:59<04:57, 11.89s/it]
 17%|███████████████████████████▌                                                                                                                                         | 5/30 [00:59<04:57, 11.89s/it]Exception in thread Thread-14:
Traceback (most recent call last):
  File "/anaconda/envs/pytorch/lib/python3.9/threading.py", line 980, in _bootstrap_inner
    self.run()
  File "/anaconda/envs/pytorch/lib/python3.9/threading.py", line 917, in run
    self._target(*self._args, **self._kwargs)
  File "/anaconda/envs/pytorch/lib/python3.9/site-packages/torch/utils/data/_utils/pin_memory.py", line 51, in _pin_memory_loop
    do_one_step()
  File "/anaconda/envs/pytorch/lib/python3.9/site-packages/torch/utils/data/_utils/pin_memory.py", line 28, in do_one_step
    r = in_queue.get(timeout=MP_STATUS_CHECK_INTERVAL)
  File "/anaconda/envs/pytorch/lib/python3.9/multiprocessing/queues.py", line 122, in get
    return _ForkingPickler.loads(res)
  File "/anaconda/envs/pytorch/lib/python3.9/site-packages/torch/multiprocessing/reductions.py", line 307, in rebuild_storage_fd
    fd = df.detach()
  File "/anaconda/envs/pytorch/lib/python3.9/multiprocessing/resource_sharer.py", line 58, in detach
    return reduction.recv_handle(conn)
  File "/anaconda/envs/pytorch/lib/python3.9/multiprocessing/reduction.py", line 189, in recv_handle
    return recvfds(s, 1)[0]
  File "/anaconda/envs/pytorch/lib/python3.9/multiprocessing/reduction.py", line 157, in recvfds
    msg, ancdata, flags, addr = sock.recvmsg(1, socket.CMSG_SPACE(bytes_size))
ConnectionResetError: [Errno 104] Connection reset by peer
 17%|███████████████████████████▌                                                                                                                                         | 5/30 [01:02<05:13, 12.53s/it]